Workbook

Sheet Division 01
A1: Group | B1: Class | C1: Sub- Class | D1: Item | E1: Sub-Item | F1: Description | G1: 2018 UN COICOP | H1: 2009 PCOICOP | I1: CPC 2.1
F3: Division 01. FOOD AND NON-ALCOHOLIC BEVERAGES
F5: Division 01 covers food (01.1) and non-alcoholic beverages (01.2) purchased by the household mainly for consumption or preparation at home. It excludes food and non-alcoholic beverages that are provided as part of a food serving service (Division 11).
F7: Services for processing primary goods to produce food and non-alcoholic beverages for own consumption are also included in this Division (01.3).
F9: Food is composed of all edible goods that are purchased and consumed by the household with the purpose of nourishing. It includes: cereals and cereal products; meat; fish and other seafood; milk, other dairy products and eggs; oils and fats; fruit and nuts; vegetables, tubers, plantains, cooking bananas and pulses; sugar, confectionery and desserts; salt, sauces and condiments, spices and culinary herbs and seeds.
F11: Division 01 also includes baby food and ready-made food that can be eaten as it is or after heating. Non-alcoholic beverages include drinks that do not contain any alcohol.
A13: 01.1 | F13: FOOD
F15: Food purchased by the household mainly for consumption or preparation at home. It excludes food that is provided as part of a food serving service.
F17: Food is composed of all edible goods that are purchased and consumed by the household with the purpose of nourishing. It includes: cereals and cereal products; meat; fish and other seafood; milk, other dairy products and eggs; oils and fats; fruit and nuts; vegetables, tubers, plantains, cooking bananas and pulses; sugar, confectionery and desserts; salt, sauces and condiments, spices and culinary herbs and seeds.
F19: This group includes:
F21: - products that need to be cooked and further prepared as well as ready-made food.
F23: This group excludes:
F25: - local delivery services of food or drinks, when separately invoiced (07.4.9.2);
F26: - products for animal feeding (09.3.2.2);
F27: - food provided by food serving services (Division 11).
B30: 01.1.1 | F30: Cereals and cereal products (ND)
C32: 01.1.1.1 | F32: Cereals (ND)
F34: Dried grains of cereals, whether or not broken or precooked (steamed), but not further prepared.
F36: This subclass includes:
F38: - wheat;
F40: - rice, including parboiled rice;
F42: - sorghum;
F44: - barley;
F46: - millet;
F48: - maize (corn);
F50: - quinoa;
F52: - teff;
F54: Includes also:
F56: - bulgur;
... F86: - seeds for planting (09.3.1.2).
D88: 01.1.1.11 | E88: 01.1.1.110 | F88: Wheat | G88: 01.1.1.11 | H88: 01.1.131p | I88: 01112
D89: 01.1.1.12 | F89: Rice
E90: 01.1.1.121 | F90: Rice, except NFA rice, well milled | G90: 01.1.1.12 | H90: 01.1.111 | I90: 23161p
E91: 01.1.1.122 | F91: Rice, except NFA rice, regular milled | G91: 01.1.1.12 | H91: 01.1.113 | I91: 23161p
E92: 01.1.1.123 | F92: Rice, except NFA rice, special | G92: 01.1.1.12 | H92: 01.1.112p 01.1.119p | I92: 23161p
E93: 01.1.1.124 | F93: Rice, except NFA rice, over milled, broken rice | G93: 01.1.1.12 | H93: 01.1.115 | I93: 23161p
E94: 01.1.1.125 | F94: NFA Rice | G94: 01.1.1.12 | H94: 01.1.114 | I94: 23161p
E95: 01.1.1.126 | F95: Rice, under milled, brown | G95: 01.1.1.12 | H95: 01.1.112p | I95: 23162p
E96: 01.1.1.127 | F96: Rice, under milled, red | G96: 01.1.1.12 | H96: 01.1.119p | I96: 23162p
E97: 01.1.1.128 | F97: Rice, milled, glutinous | G97: 01.1.1.12 | H97: 01.1.119p | I97: 23161p
...

Sheet Division 02
A1: Group | B1: Class | C1: Sub- Class | D1: Item | E1: Sub-Item | F1: Description | G1: 2018 UN COICOP | H1: 2009 PCOICOP | I1: CPC 2.1
F3: DIVISION 02. ALCOHOLIC BEVERAGES, TOBACCO AND NARCOTICS | G3: =D3
F5: Division 02 covers the purchase of alcoholic beverages (02.1) and of tobacco products (02.3) and narcotics (02.4), regardless of where these are consumed but not provided as part of a food and beverage serving service.
F7: Also includes low and non-alcoholic beverages, which are generally alcoholic, such as non-alcoholic beer. Services for the production of alcohol for own consumption (02.2) are also included in this Division.
F9: It excludes alcoholic beverages purchased for immediate consumption in hotels restaurants, cafés, bars, kiosks, street vendors, automatic vending machines, etc. (11.1.1).
A11: 02.1 | F11: ALCOHOLIC BEVERAGES | G11: =C11
F13: The beverages classified here include low or non-alcoholic beverages which generally contain some alcohol.
B15: 02.1.1 | C15: 02.1.1.0 | D15: 02.1.1.00 | F15: Spirits and liquors (ND)
E17: 02.1.1.001 | F17: Whisky | G17: =C15 -> 02.1.1.0 | H17: 02.1.110 | I17: 24131
E18: 02.1.1.002 | F18: Rum | G18: 02.1.1.0 | H18: 02.1.120 | I18: 24131
E19: 02.1.1.003 | F19: Gin | G19: 02.1.1.0 | H19: 02.1.130 | I19: 24131
E20: 02.1.1.004 | F20: Brandy | G20: 02.1.1.0 | H20: 02.1.140 | I20: 24131
E21: 02.1.1.005 | F21: Vodka (lambanog, etc.) | G21: 02.1.1.0 | H21: 02.1.150 | I21: 24131
E22: 02.1.1.006 | F22: Tequila | G22: 02.1.1.0 | H22: 02.1.190 p | I22: 24131
E23: 02.1.1.009 | F23: Other spirits and liquors, n.e.c. | G23: 02.1.1.0 | H23: 02.1.190 p | I23: 24139
B25: 02.1.2 | F25: Wine (ND) | G25: =C25
C27: 02.1.2.1 | D27: 02.1.2.10 | F27: Wine from grapes (ND)
E28: 02.1.2.101 | F28: Champagne and sparkling wines | G28: =C27 -> 02.1.2.1 | H28: 02.1.270 | I28: 24211
E29: 02.1.2.102 | F29: Wine from grapes other than champagne and sparkling wine | G29: 02.1.2.1 | H29: 02.1.290 p | I29: 24212
C31: 02.1.2.2 | D31: 02.1.2.20 | F31: Wine from other sources (ND)
E32: 02.1.2.201 | F32: Tuba (palm) wine | G32: =C31 -> 02.1.2.2 | H32: 02.1.210 | I32: 24220
E33: 02.1.2.202 | F33: Basi wine | G33: 02.1.2.2 | H33: 02.1.220 | I33: 24220
E34: 02.1.2.203 | F34: Mango wine | G34: 02.1.2.2 | H34: 02.1.230 | I34: 24220
E35: 02.1.2.204 | F35: Wine based aperitifs (ube wine, rice wine (sake), kasuy (cashew) wine, etc.) | G35: 02.1.2.2 | H35: 02.1.240 | I35: 24220
E36: 02.1.2.205 | F36: Cider and perry | G36: 02.1.2.2 | H36: 02.1.250 | I36: 24230
E37: 02.1.2.206 | F37: Fortified wines | G37: 02.1.2.2 | H37: 02.1.260 | I37: 24220
E38: 02.1.2.207 | F38: Lambanog wine | G38: 02.1.2.2 | H38: 02.1.290p | I38: 24220
E39: 02.1.2.208 | F39: Calamansi wine | G39: 02.1.2.2 | H39: 02.1.290p | I39: 24220
E40: 02.1.2.209 | F40: Other wine from other sources (e.g. medicinal wine (sioktong), duhat (plum) wine , bignay/bugnay (wild berry wine), strawberry wine, raisin wine, duhat wine, etc.) | G40: 02.1.2.2 | H40: 02.1.290p | I40: 24220
B42: 02.1.3 | C42: 02.1.3.0 | D42: 02.1.3.00 | F42: Beer (ND)
E44: 02.1.3.001 | F44: Beer made from malt | G44: =C42 -> 02.1.3.0 | H44: 02.1.310 | I44: 24310
E45: 02.1.3.002 | F45: Ale | G45: 02.1.3.0 | H45: 02.1.320 | I45: 24320
E46: 02.1.3.003 | F46: Lager | G46: 02.1.3.0 | H46: 02.1.330 | I46: 24320
E47: 02.1.3.004 | F47: Porter | G47: 02.1.3.0 | H47: 02.1.340 | I47: 24320
E48: 02.1.3.005 | F48: Low and non-alcoholic beer | G48: 02.1.3.0 | H48: 02.1.350 | I48: 24320
E49: 02.1.3.009 | F49: Other beer, n.e.c | G49: 02.1.3.0 | H49: 02.1.390 | I49: 24320
B51: 02.1.9 | C51: 02.1.9.0 | D51: 02.1.9.00 | F51: Other alcoholic beverages (ND)
E53: 02.1.9.001 | F53: Mixed alcohol-based drinks (gin pomelo, shandy, cola beer) | G53: =C51 -> 02.1.9.0 | H53: NEW | I53: 24139
E54: 02.1.9.009 | F54: Other alcoholic beverages, n.e.c. | G54: 02.1.9.0 | H54: NEW | I54: 24139
A56: 02.2 | B56: 02.2.0 | C56: 02.2.0.0 | D56: 02.2.0.00 | E56: 02.2.0.000 | F56: ALCOHOL PRODUCTION SERVICES
...

Sheet Completeness(1)
A1: 01.1.111
A2: 01.1.112
A3: 01.1.113
A4: 01.1.114
A5: 01.1.115
A6: 01.1.119
A7: 01.1.121
A8: 01.1.122
A9: 01.1.123
A10: 01.1.124
A11: 01.1.125
A12: 01.1.126
... A294: 01.2.249

Sheet Division 03
A1: Group | B1: Class | C1: Sub- Class | D1: Item | E1: Sub-Item | F1: Description | G1: 2018 UN COICOP | H1: 2009 PCOICOP | I1: CPC 2.1
F3: DIVISION 03. CLOTHING AND FOOTWEAR
F5: Division 03 covers all clothing materials, garments, articles and accessories (03.1), footwear (03.2), and related services including cleaning, repair and hire of clothing (03.1.4.) and footwear (03.2.2). The purchase of second-hand clothing and footwear should be included in the same classes as the new articles as the purpose is the same. Unisex garments and footwear should be classified according to the gender of the person wearing them.
F7: Excludes sport-and game-specific sports- and footwear (09.2.2.1).
A9: 03.1 | F9: CLOTHING | G9: =C9
F11: The clothing classified in this group covers materials purchased to be transformed into clothing, garments and accessories and services related to clothing.
F13: Made-to-measure refers to the service of providing custom fitted clothing when the retailer supplies all of the materials and is included in Group 03.1.2 (Garments) as the cost of the garment usually outweighs the cost of the service. Tailoring refers to creating clothing garments where the main material is supplied by the customer and is classified in Group 03.1.4 (Cleaning, repair, tailoring and hire of clothing) as the service is the higher expenditure.
B15: 03.1.1 | C15: 03.1.1.0 | D15: 03.1.1.00 | F15: Clothing materials (SD)
F17: This sub-class includes:
F19: - clothing materials of natural fibres, of synthetic fibres and of their mixtures;
F20: - leather, fur, fusible webbing, wadding and felt filling for making wearing apparel.
F22: This sub-class excludes:
F23: - furnishing fabrics (05.2.1.1).
E25: 03.1.1.001 | F25: Cotton and linens | G25: =C15 -> 03.1.1.0 | H25: 03.1.110 | I25: 26160 p
E26: 03.1.1.002 | F26: Clothing made from synthetic fibers | G26: 03.1.1.0 | H26: 03.1.120 | I26: 26710 p
E27: 03.1.1.009 | F27: Other clothing materials, n.e.c. | G27: 03.1.1.0 | H27: 03.1.190 | I27: 26510 p
B29: 03.1.2 | F29: Garments (SD) | G29: =C29
F31: Garments for men or boys, women or girls and infants, either ready-to-wear or made-to-measure, in all materials (including leather, furs, plastics and rubber), for everyday wear, for sport or for work.
F33: This class includes:
F35: - capes, overcoats, raincoats, anoraks, parkas, blousons, jackets, trousers, waistcoats, suits, costumes, dresses, skirts, etc.;
F37: - shirts, blouses, pullovers, sweaters, cardigans, shorts, swimsuits, tracksuits, jogging suits, sweatshirts, t-shirts, leotards, etc.;
F39: - vests, underpants, socks, stockings, tights, petticoats, brassières, knickers, slips, girdles, corsets, body stockings, etc.;
F41: - pajamas, nightshirts, nightdresses, housecoats, dressing gowns, bathrobes, etc.;
F43: - traditional garments.
F45: This class excludes:
F47: - tailoring services when the customer supplies the material (03.1.4.2);
F49: - articles of medical hosiery, such as elasticated stockings (06.1.2.2);
F51: - babies’ napkins, cloth diapers, cloth nappies (13.2.9.1).
C53: 03.1.2.1 | D53: 03.1.2.10 | F53: Garments for men or boys (SD)
F55: This subclass includes either ready-to-wear or made-to-measure, in all materials (including leather, furs, plastics and rubber), for everyday wear, for sport or for work.
E57: 03.1.2.101 | F57: Pants, shorts | G57: =C53 -> 03.1.2.1 | H57: 03.1.211 03.1.231 03.1.241 | I57: 28231
E58: 03.1.2.102 | F58: T-shirts, polo shirts, undershirts, camisatsino | G58: 03.1.2.1 | H58: 03.1.212 03.1.232 03.1.242 | I58: 28232
E59: 03.1.2.103 | F59: Underwear (supporter, brief, etc.) | G59: 03.1.2.1 | H59: 03.1.213 03.1.233 03.1.243 | I59: 28232
E60: 03.1.2.104 | F60: Socks, sports socks | G60: 03.1.2.1 | H60: 03.1.214 03.1.234 03.1.244 | I60: 28232
E61: 03.1.2.105 | F61: Suits, coats, jackets, raincoats, sweater, capes and trousers | G61: 03.1.2.1 | H61: 03.1.235 03.1.245 | I61: 28231
E62: 03.1.2.106 | F62: Track suits, swimwear, jogging suits, sweatshirts | G62: 03.1.2.1 | H62: 03.1.281 03.1.282 03.1.284 03.1.285 | I62: 28236
E63: 03.1.2.109 | F63: Other garments for men or boys, n.e.c. | G63: 03.1.2.1 | H63: 03.1.219 | I63: 28231 28232 28238
C65: 03.1.2.2 | D65: 03.1.2.20 | F65: Garments for women or girls (SD)
E67: 03.1.2.201 | F67: Dress, suits | G67: =C65 -> 03.1.2.2 | H67: 03.1.221 03.1.251 03.1.261 | I67: 28233
E68: 03.1.2.202 | F68: Pants, shorts, skirts | G68: 03.1.2.2 | H68: 03.1.222 03.1.252 03.1.262 | I68: 28233
...

Sheet Division 04
A1: Division | B1: Group | C1: Class | D1: Sub-Class | E1: Item | F1: Sub-Item | G1: Description | H1: 2018 UN COICOP | I1: 2009 PCOICOP | J1: CPC 2.1
A3: 04 | G3: DIVISION 04. HOUSING, WATER, ELECTRICITY, GAS AND OTHER FUELS | H3: =D3
G5: Division 04 covers goods and services for the use of the house or dwelling, its maintenance and repair, the supply of water and miscellaneous services related to the dwelling and energy used for heating or cooling. Actual rentals and imputed rentals (according to national accounts (SNA 2008)) for main or secondary residences are classified in Groups 04.1 and 04.2, respectively.
G7: Maintenance, repair and security of the dwelling include materials for repair purchased with the intention of undertaking the repair and maintenance themselves, as well as the repair services purchased from enterprises. It should be noted that only expenditures on materials and services for minor repairs are covered by Group 04.3. Expenditures on materials and services for major maintenance and repair are not part of individual consumption expenditures of households and are thus out of scope of the classification. This refers especially to owner-occupiers; tenants will not make such expenditures on major maintenance and repair at all as they are not the owner of the dwelling.
B9: 04.1 | G9: ACTUAL RENTALS FOR HOUSING | H9: =D9
G11: Rentals normally include payment for the use of the land on which the property stands, the dwelling occupied, the fixtures and fittings for heating, plumbing, lighting, etc., and, in the case of a dwelling let furnished, the furniture.
G13: Rentals also include payment for the use of a garage to provide parking in connection with the dwelling.
G15: The garage does not have to be physically contiguous to the dwelling; nor does it have to be leased from the same landlord.
G17: Rentals do not include payment for the use of garages or parking spaces not providing parking in connection with the dwelling (07.2.4). Nor do they include charges for water supply (04.4.1), refuse collection (04.4.2) and sewage collection (04.4.3); co-proprietor charges for caretaking, gardening, stairwell cleaning, heating and lighting, maintenance of lifts and refuse disposal chutes, etc. in multi-occupied buildings (04.4.4); charges for electricity (04.5.1) and gas (04.5.2); charges for heating and hot water supplied by district heating plants (04.5.5).
G19: Each household has a principal dwelling (sometimes also designated as main or primary home), usually defined with reference to time spent there, whose location defines the country of residence and place of usual residence of this household and of all its members. All other dwellings (owned or leased by the household) are considered secondary dwellings.
G21: This group includes:
G22: - rentals actually paid by tenants or subtenants occupying unfurnished or furnished premises as their main residence.
G24: Includes also:
G25: - payments by households occupying a room in a hotel or boarding house as their main residence.
G27: This group excludes:
G28: - accommodation services of educational establishments and hostels (11.2.0.9);
G29: - retirement homes for elderly persons (13.3.0.2).
C31: 04.1.1 | D31: 04.1.1.0 | G31: Actual rentals paid by tenants for main residence (S)
G33: This class includes:
G34: - rentals actually paid by tenants or subtenants occupying unfurnished or furnished premises as their main residence.
G36: Includes also:
G37: - payments by households occupying a room in a hotel or boarding house as their main residence.
G39: This class excludes:
G40: - garage rentals to provide parking and storage in connection with the dwelling (04.1.2.2);
G41: - accommodation services of educational establishments and hostels (11.2.0.9);
G42: - retirement homes for elderly persons (13.3.0.2).
E44: 04.1.1.01 | G44: Rentals actually paid by tenants or subtenants occupying unfurnished or furnished premises as their main residence.
F45: 04.1.1.011 | G45: Actual rentals paid by tenants or subtenants occupying unfurnished premises as their main residence | H45: 04.1.1.0 | I45: 04.1.110 | J45: 72111p
F46: 04.1.1.012 | G46: Actual rentals paid by tenants or subtenants occupying furnished premises as their main residence | H46: 04.1.1.0 | I46: 04.1.120 | J46: 72111p
E48: 04.1.1.02 | F48: 04.1.1.020 | G48: Payments by households occupying a room in a hotel or boarding house as their main residence. | H48: 04.1.1.0 | I48: 04.1.130 | J48: 72111p
E50: 04.1.1.09 | F50: 04.1.1.090 | G50: Other actual rentals paid by tenants for main residence (S), n.e.c. | H50: 04.1.1.0 | I50: 04.1.190 | J50: 72111p
C52: 04.1.2 | G52: Other actual rentals (S) | H52: =D52
G54: This class includes:
G55: - rentals actually paid for secondary residences;
G56: - rentals of self-storage units;
G57: - garage rentals.
G59: This class excludes:
G60: - accommodation services of holiday villages and holiday centres (11.2.0.2).
D62: 04.1.2.1 | E62: 04.1.2.10 | F62: 04.1.2.100 | G62: Actual rentals paid by tenants for secondary residences (S) | H62: =D62 -> 04.1.2.1 | I62: 04.1.200 | J62: 72111p
D64: 04.1.2.2 | G64: Garage rentals and other rentals paid by tenants (S)
...

Sheet Completeness(4)
A1: 04.1.110
A2: 04.1.120
A3: 04.1.130
A4: 04.1.190
A5: 04.1.200
A6: 04.1.140
A7: 04.2.110
A8: 04.2.210
A9: 04.2.220
A10: 04.3.110
A11: 04.3.120
A12: 04.3.130
... A55: 04.5.520

Sheet Division 05
A1: Division | B1: Group | C1: Class | D1: Sub-Class | E1: Item | F1: Sub-Item | G1: Description | H1: 2018 UN COICOP | I1: 2009 PCOICOP | J1: CPC 2.1
A3: 05 | G3: DIVISION 05. FURNISHINGS, HOUSEHOLD EQUIPMENT AND ROUTINE HOUSEHOLD MAINTENANCE
G5: Division 05 covers a wide range of products for the equipment of the house or dwelling and the household durables, semi-durables and non-durable as well as some kind of household services. Division 05 includes all kinds of furniture and lightning equipment (05.1), household textiles (05.2), major and smaller electric household appliances (05.3), glassware, tableware and household utensils (05.4), tools and equipment for house and garden (05.5), and goods for the routine household maintenance (05.6).
G7: It also includes repair, installation and rental services of the goods.
G9: Domestic services by paid staff in private service, supplied by enterprises or self-employed persons are included, as well as window cleaning and disinfecting services, dry-cleaning and laundering of household textiles and carpets (05.6.2).
B11: 05.1 | G11: FURNITURE, FURNISHINGS, AND LOOSE CARPETS
C13: 05.1.1 | G13: Furniture, furnishings and loose carpets (D)
G15: This class includes:
G17: - sofas, couches, tables, chairs, cupboards, chests of drawers and bookshelves, hanger stands, coat stands;
G19: - bunk beds, baby furniture, such as cradles, highchairs and play-pens;
G21: - beds, mattresses, base-mattresses, (tatamis), wardrobes, bedside tables;
G23: - kitchen tables and chairs, cupboards and surfaces;
G25: - furniture primarily for bathroom use;
G27: - furniture primarily for gardens use;
G29: - wrought iron benches and tables, arbours;
G31: - small garden houses to store garden tools and machines;
G33: - camping furniture;
G35: - lighting equipment, such as ceiling lights, standard lamps, globe lights and bedside lamps, light and LED strings.
G37: This class also includes:
... G81: - works of art and antique furniture acquired primarily as stores of value (capital formation).
D83: 05.1.1.1 | E83: 05.1.1.10 | G83: Household furniture (D)
F84: 05.1.1.101 | G84: Beds, sofas, couches, cupboards, chest of drawers, bookshelves, tables and chairs (other than kitchen and dining set) | H84: =D83 -> 05.1.1.1 | I84: 05.1.110p | J84: 38111p 38112p 38119p
F85: 05.1.1.102 | G85: Base mattresses, mattresses, (tatamis), bathroom cabinets | H85: 05.1.1.1 | I85: 05.1.150 | J85: 38150p 38140p
F86: 05.1.1.103 | G86: Baby furniture such as cradles, high- chairs and play-pens | H86: 05.1.1.1 | I86: 05.1.160 | J86: 38140p
F87: 05.1.1.104 | G87: Kitchen tables and chairs (dining set) | H87: 05.1.1.1 | I87: 05.1.110p | J87: 38130p 38140p
F88: 05.1.1.105 | G88: Hanger and coat stands | H88: 05.1.1.1 | I88: 05.1.190p | J88: 38140p
F89: 05.1.1.106 | G89: Furniture primarily for bathroom use | H89: 05.1.1.1 | I89: 05.1.150p 05.1.190p | J89: 38140p
F90: 05.1.1.109 | G90: Other household furniture, n.e.c. | H90: 05.1.1.1 | I90: 05.1.190p | J90: 38140p
D92: 05.1.1.2 | E92: 05.1.1.20 | G92: Garden and camping furniture (D)
F93: 05.1.1.201 | G93: Wrought iron benches and tables | H93: 05.1.1.2 | I93: 05.1.170p 05.1.190p | J93: 38140p
F94: 05.1.1.202 | G94: Arbors | H94: 05.1.1.2 | I94: 05.1.170p 05.1.190p | J94: 38140p
F95: 05.1.1.203 | G95: Small garden houses to store garden tools and machines | H95: 05.1.1.2 | I95: 05.1.170p 05.1.190p | J95: 38140p
F96: 05.1.1.209 | G96: Other garden and camping furniture, n.e.c. | H96: 05.1.1.2 | I96: 05.1.170p 05.1.190p | J96: 38140p
D98: 05.1.1.3 | E98: 05.1.1.30 | G98: Lighting equipment (D)
F99: 05.1.1.301 | G99: Ceiling lights | H99: =D98 -> 05.1.1.3 | I99: 05.1.120p | J99: 46531p
F100: 05.1.1.302 | G100: Standard lamps | H100: 05.1.1.3 | I100: 05.1.120p | J100: 46531p
F101: 05.1.1.303 | G101: Globe lights | H101: 05.1.1.3 | I101: 05.1.120p | J101: 46531p
F102: 05.1.1.304 | G102: Lampshade | H102: 05.1.1.3 | I102: 05.1.120p | J102: 46531p
F103: 05.1.1.305 | G103: LED strings | H103: 05.1.1.3 | I103: 05.1.120p | J103: 46539p
F104: 05.1.1.306 | G104: Ring light | H104: 05.1.1.3 | I104: 05.1.120p | J104: 46539p
...

Sheet Division 06
A1: Division | B1: Group | C1: Class | D1: Sub-Class | E1: Item | F1: Sub-Item | G1: Description | H1: 2018 UN COICOP | I1: 2009 PCOICOP | J1: CPC 2.1
A3: 06 | G3: DIVISION 06. HEALTH | H3: =D3
G5: Division 06 covers four main categories, one of which concerns medicine and health products (06.1), while the three other concern health services. Specifically, outpatient care services that do not require an overnight stay (06.2); inpatient care services provided during an overnight stay (06.3); diagnostic imaging services, medical laboratory services, patient emergency transportation and emergency rescue services (06.4). Medicines and health products (06.1) cover all products that are separately invoiced from health services except when administered under the direct supervision of a health care professional during an overnight stay (06.3). Services and products included in Division 06 are those that can only be used in response to a health need. These services and products aim at preventing the occurrence of illnesses, diseases (e.g. through vaccination); cure from illnesses, diseases, injuries; relieving symptoms of illnesses, diseases, injuries; reduce the severity of illnesses, diseases, injuries; protect against exacerbation and/or complication of illnesses, diseases, injuries; restoring the health status or maintaining/preventing the deterioration of a health condition. The division also includes services provided by health care professional purely for aesthetic beautification purposes (e.g. cosmetic surgery; dental work to whiten teeth). Division 06 excludes food believed to be highly beneficial to health, especially food grown organically as well as foods or food ingredients that have been shown to affect specific functions or system of the body (Division 01).
B7: 06.1 | G7: MEDICINES AND HEALTH PRODUCTS | H7: =D7
G9: This group includes:
G11: - medicines, vaccines, pharmaceutical preparations, medical devices, assistive products and other health-related products used for the prevention, diagnosis and treatment of illnesses, diseases, injuries and purchased by individuals or households, either with or without a prescription, usually from pharmacies, health facilities or medical/assistive equipment suppliers and from Internet reliable sources. They are intended for consumption or use outside a health facility or institution.
G13: This group excludes:
G14: - nutritional supplements and fortified food products (01.1.9.9);
G15: - medicines and health products supplied directly by a health care provider to outpatients (no overnight stay) or inpatients (overnight stay) for consumption outside a health facility or institution are to be classified as outpatient services (06.2) or inpatient services (06.3), if not separately identifiable from the service;
G16: - services fees to dispense medicines charged by a health practitioner during an outpatient service (06.2) or an inpatient service (06.3) if not separately identifiable from the service;
G17: - veterinary products (09.3.2.2);
G18: - products for personal hygiene or personal care including beauty products and creams (13.1) (e.g. aromatherapy products and slimming and beauty enhancing creams).
C20: 06.1.1 | G20: Medicines (ND) | H20: =D20
D22: 06.1.1.1 | G22: Medicines, vaccines and other pharmaceutical preparations (ND)
G24: This sub-class includes:
G25: - all medicines, including branded and generic products to treat illnesses, diseases and injuries;
G26: - pharmaceutical preparations used to treat illnesses, diseases and injuries (e.g. extemporaneous ointments, syrups, capsules or other galenical substances prepared on prescription);
G27: - vaccines, hormones, oral contraceptives and other pharmaceutical products used to prevent, diagnose or treat illnesses, diseases;
G28: - vitamins and minerals;
G29: - alcohol for medical uses, fluids required for dialysis, as well as gases used in health care, such as oxygen, when the patient purchases them directly.
G31: Includes also:
G32: - service fees to dispense medicines charged by the pharmacists.
G34: This sub-class excludes:
G35: - nutritional supplements and fortified food products (01.1.9.9);
G36: - medicines and health products supplied directly by a health care provider to outpatients (no overnight stay) or inpatients (overnight stay) for consumption outside a health facility or institution are to be classified as outpatient services (06.2) or in inpatient services (06.3), if not separately identifiable from the service;
G37: - service fees to dispense medicines charged by a health practitioner during an outpatient service (06.2) or an inpatient service (06.3), if not separately identifiable from the service;
... G39: - products for personal hygiene or personal care including beauty products and creams (13.1) (e.g. aromatherapy products and slimming and beauty enhancing creams).
E41: 06.1.1.11 | F41: 06.1.1.110 | G41: Medicines, branded and generic products, to treat illnesses, diseases and injuries | H41: 06.1.1.1 | I41: 06.1.111p 06.1.112p 06.1.113p 06.1.114p 06.1.115p | J41: 35260p
E43: 06.1.1.12 | G43: Pharmaceutical preparations used to treat illnesses, diseases and injuries (e.g. extemporaneous ointments, syrups, capsules or other galenical substances prepared on prescription)
F44: 06.1.1.121 | G44: Pharmaceutical product used to treat Infections and infestations | H44: 06.1.1.1 | I44: 06.1.111p | J44: 35260p
F45: 06.1.1.122 | G45: Pharmaceutical product used to treat hypertensive and cardiovascular diseases | H45: 06.1.1.1 | I45: 06.1.112p | J45: 35260p
F46: 06.1.1.123 | G46: Pharmaceutical product for pain relief and consciousness such as analgesic, immunology such as anesthetics, and immunosuppresants | H46: 06.1.1.1 | I46: 06.1.113p | J46: 35260p
F47: 06.1.1.124 | G47: Pharmaceutical product used to treat allergies and respiratory diseases | H47: 06.1.1.1 | I47: 06.1.114p | J47: 35260p
F48: 06.1.1.125 | G48: Pharmaceutical product used to treat endocrine diseases and disorders | H48: 06.1.1.1 | I48: 06.1.115p | J48: 35260p
F49: 06.1.1.129 | G49: Other pharmaceutical products to treat illnesses, diseases and injuries, n.e.c. | H49: 06.1.1.1 | I49: 06.1.129p 06.1.192p 06.1.193p 06.1.194p 06.1.195p | J49: 35260p 35290p
E51: 06.1.1.13 | G51: Vaccines, hormones, oral contraceptives and other pharmaceutical products used to prevent, diagnose or treat illnesses, diseases
F53: 06.1.1.131 | G53: COVID-19 vaccines | H53: 06.1.1.1 | I53: 06.1.121p | J53: 35290p
F54: 06.1.1.132 | G54: Other vaccines | H54: 06.1.1.1 | I54: 06.1.121p | J54: 35290p
F55: 06.1.1.133 | G55: Hormones | H55: 06.1.1.1 | I55: 06.1.129p | J55: 35250p
F56: 06.1.1.134 | G56: Oral contraceptives | H56: 06.1.1.1 | I56: 06.1.129p | J56: 35290p
...

Sheet Division 07
A1: Division | B1: Group | C1: Class | D1: Sub-Class | E1: Item | F1: Sub-Item | G1: Description | H1: 2018 UN COICOP | I1: 2009 PCOICOP | J1: CPC 2.1
A3: 07 | G3: DIVISION 07. TRANSPORT | H3: =D3
G5: Division 07 covers four main categories of goods and services for the purpose of transportation: purchase of vehicles (07.1), goods and services for the operation of the personal transport equipment (07.2), passenger transport services (07.3), and transport services of goods (07.4).
G7: Purchase of vehicles covers motor cars, motorcycles, bicycles and animal drawn vehicles. Due to the high share of second-hand motor vehicles in private consumption expenditures, separate subclasses for new and for second-hand motor cars are distinguished.
G9: The second group concerning the operation of personal transport equipment cover parts and accessories for personal transport equipment, fuels and lubricants and the repair and maintenance of personal transport equipment. This group also includes expenditures for parking spaces in garages or in public places, expenditures for tolls and the expenditures to acquire a driving certificate.
G11: Passenger transport services are structured by the mode of transport. However, due to fact that transport tickets may cover more than one mode of transport, a class for the combined passenger transport was created (07.3.6).
G13: The fourth group covers postal and courier services, removal and storage services, and the delivery services of any kinds of goods, if charged separately.
G15: Division 07 does not cover purchases of recreational vehicles, such as camper vans, caravans, trailers, aeroplanes and boats (09.1.2).
B17: 07.1 | G17: PURCHASE OF VEHICLES | H17: =D17
G19: This group includes:
G20: - purchase of vehicles used for transport.
G22: This group excludes:
G23: - purchases of recreational vehicles, such as camper vans, caravans, trailers, aeroplanes and boats (09.1.2).
C25: 07.1.1 | G25: Motor cars (D) | H25: =D25
G27: This class includes:
G28: - motor cars, passenger vans, station wagons, estate cars, SUVs, off-road vehicles, pickup trucks, and the like with either two-wheel drive or four-wheel drive.
G30: Includes also:
G31: - racing motor vehicles and vehicles for shows.
G33: This class excludes:
G34: - invalid carriages (06.1.3.3);
G35: - camper vans (09.1.2.1);
G36: - golf carts (09.1.2.9).
D38: 07.1.1.1 | G38: New motor cars (D)
E39: 07.1.1.11 | G39: Motor cars with combustion engines
F40: 07.1.1.111 | G40: Sedan | H40: 07.1.1.1 | I40: 07.1.100p | J40: 49113p
F41: 07.1.1.112 | G41: Passenger vans, station wagons | H41: 07.1.1.1 | I41: 07.1.100p | J41: 49113p
F42: 07.1.1.113 | G42: SUVs, off-road vehicles | H42: 07.1.1.1 | I42: 07.1.100p | J42: 49113p
F43: 07.1.1.114 | G43: Pickup trucks | H43: 07.1.1.1 | I43: 07.1.100p | J43: 49113p
F44: 07.1.1.119 | G44: Other motor cars | H44: 07.1.1.1 | I44: 07.1.100p | J44: 49113p
E46: 07.1.1.12 | G46: Motor cars with electric engines
F47: 07.1.1.121 | G47: Sedan | H47: 07.1.1.1 | I47: 07.1.100p | J47: 49113p
F48: 07.1.1.122 | G48: Passenger vans, station wagons | H48: 07.1.1.1 | I48: 07.1.100p | J48: 49113p
F49: 07.1.1.123 | G49: SUVs, off-road vehicles | H49: 07.1.1.1 | I49: 07.1.100p | J49: 49113p
F50: 07.1.1.124 | G50: Pickup trucks | H50: 07.1.1.1 | I50: 07.1.100p | J50: 49113p
F51: 07.1.1.129 | G51: Other motor cars | H51: 07.1.1.1 | I51: 07.1.100p | J51: 49113p
E53: 07.1.1.13 | G53: Motor cars with hybrid engines
F54: 07.1.1.131 | G54: Sedan | H54: 07.1.1.1 | I54: 07.1.100p | J54: 49113p
F55: 07.1.1.132 | G55: Passenger vans, station wagons | H55: 07.1.1.1 | I55: 07.1.100p | J55: 49113p
F56: 07.1.1.133 | G56: SUVs, off-road vehicles | H56: 07.1.1.1 | I56: 07.1.100p | J56: 49113p
F57: 07.1.1.134 | G57: Pickup trucks | H57: 07.1.1.1 | I57: 07.1.100p | J57: 49113p
...

Sheet Division 08
A1: Division | B1: Group | C1: Class | D1: Sub-Class | E1: Item | F1: Sub-Item | G1: Description | H1: 2018 UN COICOP | I1: 2009 PCOICOP | J1: CPC 2.1
A3: 08 | G3: DIVISION 08. INFORMATION AND COMMUNICATION | H3: =D3
G5: Division 08 covers three main groups of goods and services: information and communication equipment, including equipment for the reception, recording and reproduction of sound and vision (08.1), software (08.2), and information and communication services (08.3). Information and communication services include telephone other communication services, Internet access services, TV and radio licences, fee and subscription services, including streaming services of film and music.
G7: Division 08 also includes repair, maintenance and hire of information and communication equipment.
B9: 08.1 | G9: Information and communication equipment | H9: =D9
C11: 08.1.1 | D11: 08.1.1.0 | E11: 08.1.1.00 | G11: Fixed telephone equipment (D)
G13: This sub-class includes:
G14: - telephones, radio-telephones, telefax machines, telephone-answering machines and telephone loudspeakers.
G16: This sub-class excludes:
G17: - telefax and telephone-answering facilities provided by personal computers (08.1.3.1).
F19: 08.1.1.001 | G19: Telephones | H19: 08.1.1.0 | I19: 08.2.020p | J19: 47221p
F20: 08.1.1.002 | G20: Radio-telephones | H20: 08.1.1.0 | I20: 08.2.020p | J20: 47221p
F21: 08.1.1.003 | G21: Telefax machines | H21: 08.1.1.0 | I21: 08.2.030 | J21: 47229p
F22: 08.1.1.004 | G22: Telephone-answering machines | H22: 08.1.1.0 | I22: 08.2.040 | J22: 47229p
F23: 08.1.1.005 | G23: Telephone loudspeakers. | H23: 08.1.1.0 | I23: 08.2.020p | J23: 47229p
F24: 08.1.1.009 | G24: Other fixed telephone equipment | H24: 08.1.1.0 | I24: 08.2.020p | J24: 47229p
C26: 08.1.2 | D26: 08.1.2.0 | G26: Mobile telephone equipment (D)
G28: This sub-class includes:
G29: - mobile telephone handsets, including devices with several functions;
G30: - smartphones.
E32: 08.1.2.01 | F32: 08.1.2.010 | G32: Mobile (cellular) phones | H32: 08.1.2.0 | I32: 08.2.010p | J32: 47222p
E33: 08.1.2.02 | F33: 08.1.2.020 | G33: Smartphones | H33: 08.1.2.0 | I33: 08.2.010p | J33: 47222p
E34: 08.1.2.09 | F34: 08.1.2.090 | G34: Other mobile telephone handsets | H34: 08.1.2.0 | I34: 08.2.010p | J34: 47222p
C37: 08.1.3 | G37: Information processing equipment (D) | H37: =D37
G39: This class includes:
G40: - personal computers, printers, scanners, monitors, projectors, augmented reality (AR) and virtual reality (VR) head mounts, modems, routers, network switches and the like, keyboards, mice, digitizers;
G41: - tablets;
G42: - calculators, including pocket calculators;
G43: - typewriters and word processors (device);
G44: - toner and ink cartridges, laser printer drums, typewriter ribbons.
G46: Includes also:
G47: - telefax and telephone-answering facilities running on computers.
G49: This class excludes:
G50: - computer software packages, such as operating systems, applications, languages, etc. (08.2.0.0);
G51: - video game software; video game computers and consoles (09.2.1.1);
G52: - removable media containing books, dictionaries, encyclopaedias, foreign language trainers, multimedia presentations, etc. in the form of software (09.7.1).
D54: 08.1.3.1 | E54: 08.1.3.10 | G54: Computers, laptops and tablets (D)
G56: This sub-class includes:
G57: - desktop computers and laptops;
G58: - tablets.
...

Sheet Division 09
A1: Group | B1: Class | C1: Sub-Class | D1: Item | E1: Sub-Item | F1: Description | G1: 2018 UN COICOP | H1: 2009 PCOICOP | I1: CPC 2.1
F3: DIVISION 09. RECREATION, SPORT AND CULTURE | G3: =C3
F5: Division 09 covers a wide range of goods and services for recreation, sport and culture and it structured into eight groups. The first group (09.1) covers recreation durables: photographic equipment, other major durables for recreation, such as camper vans, boats, yachts, airplanes and the like). Group 09.2 covers non-major durable recreational goods, such as games and toys, including video game computers, celebration articles, equipment for sport, camping and open-air recreation. The third group (09.3) covers garden products, plants and flowers, the purchases of pets, and expenditures for pets, excluding veterinary services). Recreational services (09.4) cover rental, maintenance and repair of goods classified in Division 09, veterinary and other services for pets, recreational and leisure services, such as amusement parks, games of chance and expenditures for sporting services, both expenditures for practising sports as well as expenditures for attendance of sport events.
F7: Group 09.5 covers cultural goods, such as musical instruments and audio-visual media, followed by cultural services (09.6), which cover cinemas, theatres, concerts, museums, and other cultural sites, as well as photographic services. Whether books or newspapers are in printed or electronic form is irrelevant for classifying them under 09.7.
F9: The last group (09.8) covers package holidays, which as a bundle include all kinds of services, such as transportation, accommodation, foods provision, tour guide, etc. Expenditures for package holiday cannot be split into its components and thus a separate classification category was created. The length of the package holiday and whether the holiday destination is within the home country or outside does not matter.
A11: 09.1 | F11: RECREATIONAL DURABLES | G11: =C11
F12: This group covers recreation durables: photographic equipment, other major durables for recreation, such as camper vans, boats, yachts, aeroplanes and the like).
B14: 09.1.1 | F14: Photographic and cinematographic equipment and optical instruments (D) | G14: =C14
F16: This class includes:
F18: - still cameras, movie cameras and sound-recording cameras, film and slide projectors, enlargers and film processing equipment;
F20: - video cameras, including camcorders, action cameras;
F22: - screens, viewers, lenses (including zoom lenses), lenses, flash attachments, filters, exposure meters, etc.;
F24: - photographic developer and photographic paper;
F26: - binoculars, microscopes, telescopes and compasses
F28: This class also includes:
F30: - separate material purchased by households with the intention of undertaking the repairs themselves;
F32: - photographic and cinematographic films;
F34: - batteries and chargers for cameras and other photographic and cinematographic equipment.
F36: This group excludes:
F38: - dash cameras (07.2.1.3);
F40: - web cameras (08.1.3.2)
C42: 09.1.1.1 | D42: 09.1.1.10 | F42: Cameras (D)
E43: 09.1.1.101 | F43: Still camera (film or digital ) | G43: 09.1.1.1 | H43: 09.1.210 p | I43: 48322 p
E44: 09.1.1.102 | F44: Movie cameras | G44: 09.1.1.1 | H44: 09.1.210 p | I44: 48322 p
E45: 09.1.1.103 | F45: Video cameras, including camcorders, action cameras | G45: 09.1.1.1 | H45: 09.1.210 p | I45: 48322 p
E46: 09.1.1.104 | F46: Drones with cameras | G46: 09.1.1.1 | H46: 09.1.299 p | I46: 48321 p
E47: 09.1.1.105 | F47: Film and slide projectors | G47: 09.1.1.1 | H47: 09.1.299 p | I47: 48321 p
E48: 09.1.1.106 | F48: Enlargers and film processing equipment | G48: 09.1.1.1 | H48: 09.1.220 p | I48: 48329 p
E49: 09.1.1.109 | F49: Other cameras, n.e.c. | G49: 09.1.1.1 | H49: 09.1.210 p 09.1.299 p | I49: 48321 p 48322 p
C51: 09.1.1.2 | D51: 09.1.1.20 | F51: Accessories for photographic and cinematographic equipment (D)
E52: 09.1.1.201 | F52: Screens | G52: 09.1.1.2 | H52: 09.1.220 p | I52: 48329 p 48353 p
E53: 09.1.1.202 | F53: Lenses (including zoom lenses) | G53: 09.1.1.2 | H53: 09.1.220 p | I53: 48329 p 48353 p
E54: 09.1.1.203 | F54: Filters and exposure meters | G54: 09.1.1.2 | H54: 09.1.220 p | I54: 48329 p 48353 p
E55: 09.1.1.204 | F55: Photographic developer and photographic paper | G55: 09.1.1.2 | H55: 09.1.220 p | I55: 48329 p 48353 p
E56: 09.1.1.205 | F56: Photographic and cinematographic films | G56: 09.1.1.2 | H56: 09.1.220 p | I56: 48322 p 48329 p 48353 p
E57: 09.1.1.206 | F57: Camera specific batteries and chargers | G57: 09.1.1.2 | H57: 09.1.220 p | I57: 48329 p 48353 p
E58: 09.1.1.209 | F58: Other accessories for photographic and cinematographic equipment, n.e.c. | G58: 09.1.1.2 | H58: 09.1.291 p | I58: 48329 p 48353 p
C60: 09.1.1.3 | D60: 09.1.1.30 | F60: Optical instruments (D)
E61: 09.1.1.301 | F61: Binoculars | G61: 09.1.1.3 | H61: 09.1.230 p | I61: 48314 p
E62: 09.1.1.302 | F62: Microscopes | G62: 09.1.1.3 | H62: 09.1.230 p | I62: 48314 p
...

Sheet Division 10
A1: Group | B1: Class | C1: Sub-Class | D1: Item | E1: Sub-Item | F1: Description | G1: 2018 UN COICOP | H1: 2009 PCOICOP | I1: CPC 2.1
F3: DIVISION 10. EDUCATION SERVICES | G3: =C3
F5: Division 10 covers educational services only. The focus of Groups 10.1 to 10.4 is on formal education (that leads to degrees, certificates, or diplomas), except for non-formal and informal education e.g., Alternative Learning System (ALS). It includes education by radio or television broadcasting as well as modular, e-learning, blended learning and correspondence courses. It includes admission and registration fees as well as tuition fees.
F7: It includes other education related fees, such as camps and field trips, course fees, diploma fees, examination fees, graduation fees, laboratory fees, physical education fees, capital assessment fees, homeschool fees, etc.
F9: - Homeschool fees are expenditure or tuition fees from home-based education services (from early childhood education services up to upper secondary education services) provided by homeschool provider who are offerring home-based schooling.
F10: - Tuition fees are expenditure from school-based education services provided by public or private schools.
F12: The breakdown of educational services is based upon the level categories of the 2011 revision of the International Standard Classification of Education (ISCED 2011) of the United Nations Educational, Scientific and Cultural Organization (UNESCO) and the 2017 Philippine Standard Classification of Education (PSCED) of PSA.
F14: This Division does not include expenditures on other education related goods and services, such as:
F16: - school uniforms (03.1.2.4);
F17: - education support services, such as health-care services (06);
F18: - transport services except in the case of excursions which are part of the normal school programme (07.3.2.3);
F19: - stationery (09.7.4.0);
F20: - catering services (11.1.2.1);
F21: - accommodation services (11.2.0.3).
A23: 10.1 | F23: EARLY CHILDHOOD AND PRIMARY EDUCATION | G23: =C23
G24: =C24
B25: 10.1.0 | F25: Early chilhood and primary education (S)
F27: This clas includes:
F28: - levels 0 and 1 of ISCED 2011 and 2017 PSCED Early childhood and primary education;
F29: - literacy programmes for students too old for primary school;
F30: - education services for children with special educational needs.
F32: Includes also:
F33: - excursions which are part of the normal school programme (travel and accommodation costs).
F35: This class excludes:
F36: - child care services without educational programme (13.3.0.1).
C38: 10.1.0.1 | F38: Early childhood education services (S)
F40: This sub-class includes:
F41: - level 0 of ISCED 2011: Early childhood education is designed primarily to support children’s early cognitive, physical, social and emotional development and introduce very young children to organized instruction outside of the family context. Programmes are designed for children below the entry age to primary education and are typically centre, school-based or other institutionalized for a group of children (e.g. community-based, home-based). This education may also be provided in hospitals or in special schools or training centres;
F42: - special education services for children with special educational needs
F44: Includes also:
F45: - excursions which are part of the normal school programme (travel and accommodation costs).
F47: This sub-class excludes:
F48: - child care services without educational programme (13.3.0.1).
D50: 10.1.0.11 | F50: Public early childhood educational development programs
F52: These include expenditures on early childhood education program provided by public institutions except for special groups (i.e., I.P learner, learners with dissability).
E54: 10.1.0.111 | F54: Tuition fees | G54: 10.1.0.1 | H54: 10.1.111p | I54: 92100
E55: 10.1.0.112 | F55: Allowance for family member/s studying away from home | G55: 10.1.0.1 | H55: 10.1.112p | I55: 92100
E56: 10.1.0.119 | F56: Other educational expenses | G56: 10.1.0.1 | H56: 10.1.119p | I56: 92100
D58: 10.1.0.12 | F58: Private early childhood educational development programs
F60: These include expenditures on early childhood education program provided by private institutions except for special groups (i.e., I.P learner, learners with dissability).
...

Sheet Division 11
A1: Group | B1: Class | C1: Sub-Class | D1: Item | E1: Sub-Item | F1: Description | G1: 2018 UN COICOP | H1: 2009 PCOICOP | I1: CPC 2.1
F3: DIVISION 11. RESTAURANTS AND ACCOMMODATION SERVICES | G3: =C3
F5: Division 11 covers food and beverage serving services provided by restaurants, cafés and similar facilities, either with full, limited, or self-service, or by canteens, cafeterias or refectories at work or school and other educational establishment’s premises (11.1). The distinction between full service and limited service relates to the range of the food and beverage serving services: a service by waiters to the individual customer seated at tables will be qualified to be a full service.
F7: Accommodation (11.2) this Division includes services for visitors and other travellers away from their principal or secondary residence. If not separately invoiced, it also includes food and beverage services and other serving services, such as housekeeping, parking, laundry, swimming pools and exercise rooms, recreational facilities and conference and convention facilities.
F9: This excludes permanent principal or secondary residence accommodation (Division 04).
A11: 11.1 | F11: FOOD AND BEVERAGE SERVING SERVICES | G11: =C11
B13: 11.1.1 | F13: Restaurants, café and the like (S) | G13: =C13
F15: Food and beverages services provided by restaurants, cafés and similar eating facilities either providing full, limited, or self-service.
F17: This class includes:
F19: - tobacco that is consumed with a shisha or hookah pipes in restaurants, cafés, or shisha lounges;
F21: - narcotics purchased in coffee shops, if service charge is applied;
F23: - tips and gratuities.
F25: This class excludes:
F27: - food and beverage provided by supermarkets and markets and consumed at their premises (related products in Division 01);
F29: - food products and beverages dispensed by automatic vending machines not as a delivery service provided restaurants, cafés, buffets, bars, tearooms and similar facilities (01.1.9.1);
F31: - tobacco purchases (02.3.0);
F33: - food and beverage services on public transport, if not separately invoiced (07.3);
F35: - food and beverages delivery services, if separately invoiced (07.4.9.2);
F37: - dancing establishments and nightclubs entrance fees (09.4.6.1);
... F43: - food and beverage services provided by hotels or other lodging establishments, if not separately invoiced from accommodation (11.2).
C45: 11.1.1.1 | D45: 11.1.1.10 | F45: Restaurants, café and the like - with full service (S)
F47: Food and beverages services provided by restaurants, cafés and similar eating facilities providing full service consisting of waiter service to individual customers seated at tables, with or without entertainment.
F49: This sub-class also includes:
F51: - food and beverages provided by full-service facilities mainly serving drinks: cafés, buffets, bars, tearooms and similar;
F53: - food and beverages provided by full-service restaurants, cafés and the like and consumed off their premises; food and beverages provided by full-service restaurants, cafés and the like and home-delivered;
F55: - food and beverage full-services in hotels or other accommodation establishments, if separately invoiced from accommodation;
F57: - food and beverage full-services in establishments providing recreational, cultural, sporting or entertainment services (theatres, cinemas, sports stadiums, swimming pools, sports complexes, museums, art galleries, nightclubs, dancing establishments and similar facilities) if separately invoiced;
F59: - tobacco that is consumed with a shisha or hookah pipes in restaurants, cafés, or shisha lounges;
F61: - narcotics purchased in coffee shops, if service charge is applied;
F63: - tips and gratuities.
F65: This sub-class excludes:
F67: - food and beverage provided by supermarkets and markets and consumed at their premises (related products in Division 01);
F69: - tobacco purchases (02.3.0);
... F81: - food and beverage services in hotels or other lodging establishments, if not separately invoiced from accommodation (11.2).
E83: 11.1.1.101 | F83: Restaurants | G83: 11.1.1.1 | H83: 11.1.111p | I83: 63310
E84: 11.1.1.102 | F84: Cafes | G84: 11.1.1.1 | H84: 11.1.111p | I84: 63310p
E85: 11.1.1.103 | F85: Hotels, if food and beverages are separately invoiced | G85: 11.1.1.1 | H85: 11.2.010 | I85: 63310p
E86: 11.1.1.104 | F86: Other accommodation establishments, if separately invoiced from accommodation | G86: 11.1.1.1 | H86: 11.1.190p | I86: 63310p
E87: 11.1.1.105 | F87: Establishments providing recreational, cultural, sporting or entertainment services (e.g. theatres, cinemas, sports stadiums, swimming pools, sports complexes, museums, art galleries, nightclubs, dancing establishments and similar facilities) | G87: 11.1.1.1 | H87: 11.1.112p | I87: 63310p
E88: 11.1.1.106 | F88: Shisha lounge and the like with full service | G88: 11.1.1.1 | H88: 11.1.112p | I88: 63310p
...

Sheet Division 12
A1: Group | B1: Class | C1: Sub-Class | D1: Item | E1: Sub-Item | F1: Description | G1: 2018 UN COICOP | H1: 2009 PCOICOP | I1: CPC 2.1
F3: DIVISION 12. INSURANCE AND FINANCIAL SERVICES | G3: =C3
F5: Division 12 covers insurance (12.1) and financial services (12.2). Insurance and financial services are provided by financial corporations. These may be paid for explicitly or implicitly. Some transactions in financial assets may also involve both explicit and implicit charges. Implicit charges are not always as evident as the way in which charges are made for most goods and services and are typically calculated using a number of observable transactions. Examples of implicit charges arise from the financial services provided in association with interest charges on loans and deposits, the acquisition and disposal of financial assets and liabilities in financial markets, and insurance and pension schemes. The imputed values of expenditure on insurance and financial services are not directly observable from household income and expenditure surveys.
F7: Insurance services are subdivided by type of insurance. Financial services are subdivided by financial intermediation services indirectly measured and by the other forms of actual and indirect charges and remittance fees for financial services. For the definition and the measurement of the insurance and financial services specific national accounts concepts (2008 SNA) do apply.
A9: 12.1 | F9: INSURANCE | G9: =C9
F11: Service charges for insurance are classified by type of insurance, namely: life insurance and non-life insurance (that is, insurance in connection with the dwelling, health, transport, etc.). Service charges for multi-risk insurance covering several risks should be classified on the basis of the cost of the principal risk if it is not possible to allocate the service charges to the various risks covered.
F13: The basic method for measuring the service charge for non-life insurance is total premiums earned plus investment income earned from investing the premiums less adjusted claims incurred.
F15: The basic method for measuring the service charge for life insurance is premiums earned plus investment income earned from investing the premiums less benefits due less increases (plus decreases) in life insurance technical reserves.
B17: 12.1.1 | C17: 12.1.1.0 | F17: Life and accident insurance (S)
F19: This sub-class includes:
F21: - service charges for life insurance, annuities, death benefit insurance, education insurance, etc.
F23: Includes also:
F25: - service charges for funeral insurance;
F27: - service charges for accident insurance.
D29: 12.1.1.01 | E29: 12.1.1.010 | F29: Service charges for life insurance | G29: 12.1.1.0 | H29: 12.5.110p | I29: 71311
D30: 12.1.1.02 | E30: 12.1.1.020 | F30: Service charges for death benefit insurance | G30: 12.1.1.0 | H30: 12.5.120p | I30: 71311
D31: 12.1.1.03 | E31: 12.1.1.030 | F31: Service charges for education insurance | G31: 12.1.1.0 | H31: 12.5.130 | I31: 71311
D32: 12.1.1.04 | E32: 12.1.1.040 | F32: Service charges for annuities | G32: 12.1.1.0 | H32: NEW | I32: 71311
D33: 12.1.1.05 | E33: 12.1.1.050 | F33: Service charges for funeral insurance | G33: 12.1.1.0 | H33: 12.5.110p 12.5.120p | I33: 71311
D34: 12.1.1.06 | E34: 12.1.1.060 | F34: Service charges for accident insurance | G34: 12.1.1.0 | H34: 12.5.110p 12.5.120p | I34: 71311
B36: 12.1.2 | C36: 12.1.2.0 | F36: Insurance connected with health (S)
F38: This sub-class includes:
F40: - service charges for direct sickness insurance;
F42: - service charges for social health insurance;
F43: - service charges for disability insurance;
F45: - service charges for critical illness insurance;
F46: - service charges for long-term care insurance;
F48: - service charges for supplementary health insurance;
F50: - service charges for supplementary prescription drug insurance;
F52: - service charges for travel health insurance.
F54: Includes also:
F56: - service charges for medical transport (e.g. ambulance) insurance.
D58: 12.1.2.01 | E58: 12.1.2.010 | F58: Service charges for direct sickness insurance | G58: 12.1.2.0 | H58: 12.5.300p | I58: 71322
D59: 12.1.2.02 | E59: 12.1.2.020 | F59: Service charges for social health insurance | G59: 12.1.2.0 | H59: 12.5.300p | I59: 71322
D60: 12.1.2.03 | E60: 12.1.2.030 | F60: Service charges for disability insurance | G60: 12.1.2.0 | H60: 12.5.300p | I60: 71322
D61: 12.1.2.04 | E61: 12.1.2.040 | F61: Service charges for critical illness insurance | G61: 12.1.2.0 | H61: 12.5.300p | I61: 71322
D62: 12.1.2.05 | E62: 12.1.2.050 | F62: Service charges for long-term care insurance | G62: 12.1.2.0 | H62: 12.5.300p | I62: 71322
D63: 12.1.2.06 | E63: 12.1.2.060 | F63: Service charges for supplementary health insurance | G63: 12.1.2.0 | H63: 12.5.300p | I63: 71322
D64: 12.1.2.07 | E64: 12.1.2.070 | F64: Service charges for supplementary prescription drug insurance | G64: 12.1.2.0 | H64: 12.5.300p | I64: 71322
D65: 12.1.2.08 | E65: 12.1.2.080 | F65: Service charges for travel health insurance | G65: 12.1.2.0 | H65: 12.5.300p | I65: 71322
...

Sheet Division 13
A1: Group | B1: Class | C1: Sub-Class | D1: Item | E1: Sub-Item | F1: Description | G1: 2018 UN COICOP | H1: 2009 PCOICOP | I1: CPC 2.1
F3: DIVISION 13. PERSONAL CARE, SOCIAL PROTECTION AND MISCELLANEOUS GOODS AND SERVICES | G3: =C3
F5: Division 13 covers goods and services for personal care (13.1), jewellery and watches (13.2), services of social protection (13.3), and all other services for households, which are not classified elsewhere (13.9). Goods and services for personal care cover electric and non-electric appliances for personal care as well as hairdressing services. Goods of personal effects cover jewellery and watches, celebration and devotional articles, and travel goods and articles.
F7: Social protection services cover child-care, non-medical retirement homes for elderly persons and disabled persons, services to maintain persons in their private homes and related service. Group 13.9 cover all the other services for households, which are not classified elsewhere, such as fees for legal and administrative services, fees for real estate agencies, charges for undertaking, payment for various personal services (e.g. graphologists, bodyguards, matrimonial agencies, etc.)
F9: This division also includes religious services.
A11: 13.1 | F11: PERSONAL CARE | G11: =C11
B13: 13.1.1 | F13: Electric appliances for personal care (SD) | G13: =C13
F15: This class includes:
F17: - electric razors, hair trimmers and epilators, hand-held and hood hairdryers, straightening irons, curling tongs and styling combs, sunlamps, vibrators, electric toothbrushes and other electric appliances for dental hygiene, etc.;
F19: - repair of electric appliances for personal care.
C21: 13.1.1.1 | D21: 13.1.1.10 | E21: 13.1.1.100 | F21: Electric appliances for personal care (SD) | G21: =C21 -> 13.1.1.1 | H21: 12.1.210 | I21: 44816 p
F23: This includes the purchases of electric razors, hair trimmers and epilators, hand-held and hood hairdryers, straightening irons, curling tongs and styling combs, sunlamps, vibrators, electric toothbrushes and other electric appliances for dental hygiene, etc.
F25: This sub-class excludes repair of electric appliances for personal care (13.1.1.2).
C27: 13.1.1.2 | D27: 13.1.1.20 | E27: 13.1.1.200 | F27: Repair of electric appliances for personal care (S) | G27: =C27 -> 13.1.1.2 | H27: 12.1.220 | I27: 87151 p
F29: The cost of materials is included only if the materials are not separately invoiced.
F31: This also includes repair of electric appliances for personal care.
B33: 13.1.2 | C33: 13.1.2.0 | F33: Other appliances, articles and products for personal care (ND)
F35: This sub-class includes:
F37: - non-electric appliances: shavers, razors and hair trimmers and blades therefor, scissors, nail files, combs, shaving brushes, hairbrushes, toothbrushes, nail brushes, hairpins, curlers, personal weighing machines, scales, etc.;
F39: - articles for personal hygiene: toilet soap, medicinal soap, cleansing oil and milk, shaving soap, shaving cream and foam, toothpaste, epilation wax, paper handkerchiefs, etc.;
F41: -beauty products: lipstick, nail varnish, make-up and make-up removal products (including powder compacts, brushes and powder puffs), hair lacquers and lotions, pre-shave and after-shave products, sunbathing products and sunscreens, hair removers, perfumes and toilet waters, personal deodorants, bath products, etc.
F43: This sub-class excludes:
F45: - handkerchiefs made of fabric (03.1.3.1);
F47: - diapers for the aging population (06.1.3.3);
F49: - baby scales (06.1.2.1).
D51: 13.1.2.01 | F51: Purchase of non-electric appliances (razors and hair trimmers and blades therefor, scissors, nail files, combs, shaving brushes, hairbrushes, toothbrushes, nail brushes, hairpins, curlers, personal weighing machines, baby scales, etc.)
E52: 13.1.2.011 | F52: Razors, hair trimmers, blades and scissors | G52: 13.1.2.0 | H52: 12.1.310p | I52: 42913 p 44816 p
E53: 13.1.2.012 | F53: Nail files and nail brushes | G53: 13.1.2.0 | H53: 12.1.310p | I53: 42915 p
E54: 13.1.2.013 | F54: Combs and hairbrushes | G54: 13.1.2.0 | H54: 12.1.310p | I54: 38994 p
E55: 13.1.2.014 | F55: Toothbrushes | G55: 13.1.2.0 | H55: 12.1.310p | I55: 38993 p
E56: 13.1.2.015 | F56: Hairpins and curlers | G56: 13.1.2.0 | H56: 12.1.310p | I56: 38994 p
E57: 13.1.2.016 | F57: Personal weighing machines | G57: 13.1.2.0 | H57: 12.1.310p | I57: 43922 p
E58: 13.1.2.019 | F58: Other non-electric appliances | G58: 13.1.2.0 | H58: 12.1.310p | I58: 38999 p
